=== Cloud Resource Scheduler Log ===
Started at: Sun Mar 15 15:28:42 2026


[15:28:42] INFO: Simulation started
[15:28:42] INFO: Using Priority scheduling
[15:28:44] INFO: VM 0 arrived (Priority: 2, Burst: 1564ms)
[15:28:44] SUCCESS: VM 0 scheduled for execution
[15:28:44] INFO: VM 0 started execution (CPU: 3, Memory: 5, Storage: 7)
[15:28:45] SUCCESS: VM 0 completed execution
[15:28:47] INFO: VM 1 arrived (Priority: 0, Burst: 4745ms)
[15:28:47] SUCCESS: VM 1 scheduled for execution
[15:28:47] INFO: VM 1 started execution (CPU: 1, Memory: 7, Storage: 10)
[15:28:49] INFO: VM 2 arrived (Priority: 3, Burst: 4222ms)
[15:28:49] SUCCESS: VM 2 scheduled for execution
[15:28:49] INFO: VM 2 started execution (CPU: 3, Memory: 7, Storage: 15)
[15:28:50] INFO: VM 3 arrived (Priority: 3, Burst: 3999ms)
[15:28:50] SUCCESS: VM 3 scheduled for execution
[15:28:50] INFO: VM 3 started execution (CPU: 1, Memory: 2, Storage: 14)
[15:28:51] SUCCESS: VM 1 completed execution
[15:28:52] INFO: VM 4 arrived (Priority: 4, Burst: 2335ms)
[15:28:52] SUCCESS: VM 4 scheduled for execution
[15:28:52] INFO: VM 4 started execution (CPU: 4, Memory: 3, Storage: 5)
[15:28:53] SUCCESS: VM 3 completed execution
[15:28:53] SUCCESS: VM 2 completed execution
[15:28:54] INFO: VM 5 arrived (Priority: 4, Burst: 3255ms)
[15:28:54] SUCCESS: VM 4 completed execution
[15:28:54] SUCCESS: VM 5 scheduled for execution
[15:28:54] INFO: VM 5 started execution (CPU: 2, Memory: 6, Storage: 19)
[15:28:55] INFO: VM 6 arrived (Priority: 1, Burst: 2778ms)
[15:28:55] SUCCESS: VM 6 scheduled for execution
[15:28:55] INFO: VM 6 started execution (CPU: 4, Memory: 5, Storage: 15)
[15:28:57] INFO: VM 7 arrived (Priority: 1, Burst: 2929ms)
[15:28:57] SUCCESS: VM 5 completed execution
[15:28:57] SUCCESS: VM 6 completed execution
[15:28:57] SUCCESS: VM 7 scheduled for execution
[15:28:57] INFO: VM 7 started execution (CPU: 1, Memory: 2, Storage: 13)
[15:28:59] INFO: VM 8 arrived (Priority: 0, Burst: 4575ms)
[15:29:00] SUCCESS: VM 7 completed execution
[15:29:00] SUCCESS: VM 8 scheduled for execution
[15:29:00] INFO: VM 8 started execution (CPU: 2, Memory: 5, Storage: 5)
[15:29:00] INFO: VM 9 arrived (Priority: 0, Burst: 4033ms)
[15:29:01] SUCCESS: VM 9 scheduled for execution
[15:29:01] INFO: VM 9 started execution (CPU: 1, Memory: 2, Storage: 14)
[15:29:03] INFO: VM 10 arrived (Priority: 3, Burst: 2371ms)
[15:29:04] SUCCESS: VM 8 completed execution
[15:29:04] SUCCESS: VM 10 scheduled for execution
[15:29:04] INFO: VM 10 started execution (CPU: 4, Memory: 2, Storage: 18)
[15:29:05] SUCCESS: VM 9 completed execution
[15:29:06] SUCCESS: VM 10 completed execution
[15:29:06] INFO: VM 11 arrived (Priority: 1, Burst: 2846ms)
[15:29:07] SUCCESS: VM 11 scheduled for execution
[15:29:07] INFO: VM 11 started execution (CPU: 4, Memory: 5, Storage: 16)
[15:29:07] INFO: VM 12 arrived (Priority: 3, Burst: 2471ms)
[15:29:08] SUCCESS: VM 12 scheduled for execution
[15:29:08] INFO: VM 12 started execution (CPU: 3, Memory: 5, Storage: 10)
[15:29:09] SUCCESS: VM 11 completed execution
[15:29:10] SUCCESS: VM 12 completed execution
[15:29:10] INFO: VM 13 arrived (Priority: 1, Burst: 3531ms)
[15:29:11] SUCCESS: VM 13 scheduled for execution
[15:29:11] INFO: VM 13 started execution (CPU: 3, Memory: 3, Storage: 9)
[15:29:14] SUCCESS: VM 13 completed execution
[15:29:15] SUCCESS: Simulation completed successfully

=== Log Ended ===
